Workbook
Name Slicer_State: #N/A

Sheet Dashboard

Sheet Pivot
A3: Row Labels | B3: Revenue | C3: Profit | D3: % margin | F3: State | G3: Revenue | I3: State | J3: Profit | N3: Total Revenue | Q3: Months
A4: Lagos | B4: 13905300 | C4: 4657000 | D4: =C4/B4 -> 0.33490827 | F4: =A4 -> Lagos | G4: =B4 -> 13905300 | I4: =A4 -> Lagos | J4: =C4 -> 4657000 | N4: 47810625 | Q4: Jan
A5: Kano | B5: 10342200 | C5: 3363800 | D5: =C5/B5 -> 0.32524995 | F5: =A5 -> Kano | G5: =B5 -> 10342200 | I5: =A5 -> Kano | J5: =C5 -> 3363800 | Q5: Feb
A6: Ibadan | B6: 9441325 | C6: 2905225 | D6: =C6/B6 -> 0.30771369 | F6: =A6 -> Ibadan | G6: =B6 -> 9441325 | I6: =A6 -> Ibadan | J6: =C6 -> 2905225 | Q6: Mar
A7: Port Harcourt | B7: 7430850 | C7: 2342650 | D7: =C7/B7 -> 0.31526003 | F7: =A7 -> Port Harcourt | G7: =B7 -> 7430850 | I7: =A7 -> Port Harcourt | J7: =C7 -> 2342650 | N7: Total Profit | Q7: Apr
A8: Abuja | B8: 6690950 | C8: 1701350 | D8: =C8/B8 -> 0.2542763 | F8: =A8 -> Abuja | G8: =B8 -> 6690950 | I8: =A8 -> Abuja | J8: =C8 -> 1701350 | N8: 14970025 | Q8: May
A9: Grand Total | B9: 47810625 | C9: 14970025 | Q9: Jun
N10: Total Cost | Q10: Jul
N11: 32840600 | Q11: Aug
A12: Product Category | B12: Revenue | C12: Profit | D12: % margin | F12: Product Category | G12: Revenue | Q12: Grand Total
A13: Electronics | B13: 30035900 | C13: 9214900 | D13: =C13/B13 -> 0.3067962 | F13: =A13 -> Electronics | G13: =B13 -> 30035900 | N13: Total Order
A14: Home | B14: 13510500 | C14: 3753500 | D14: =C14/B14 -> 0.27782095 | F14: =A14 -> Home | G14: =B14 -> 13510500 | N14: 432
A15: Accessories | B15: 4264225 | C15: 2001625 | D15: =C15/B15 -> 0.46939948 | F15: =A15 -> Accessories | G15: =B15 -> 4264225 | Q15: State
A16: Grand Total | B16: 47810625 | C16: 14970025 | N16: Sum of Units | Q16: Abuja
N17: 1190 | Q17: Ibadan
Q18: Kano
A19: Channel | B19: Total Order | C19: Returned Order | D19: Return Rate | F19: Channel | G19: Return rate | M19: Channel | N19: Return Rate | Q19: Lagos
A20: In-store | B20: 208 | C20: 13 | D20: =C20/B20 -> 0.0625 | F20: =A20 -> In-store | G20: =D20 -> 0.0625 | M20: =A20 -> In-store | N20: =D20 -> 0.0625 | Q20: Port Harcourt
A21: Online | B21: 137 | C21: 15 | D21: =C21/B21 -> 0.10948905 | F21: =A21 -> Online | G21: =D21 -> 0.10948905 | M21: =A21 -> Online | N21: =D21 -> 0.10948905 | Q21: Grand Total
A22: WhatsApp | B22: 87 | C22: 10 | D22: =C22/B22 -> 0.11494253 | F22: =A22 -> WhatsApp | G22: =D22 -> 0.11494253 | M22: =A22 -> WhatsApp | N22: =D22 -> 0.11494253
A23: Grand Total | B23: 432 | C23: 38 | D23: =C23/B23 -> 0.087962963
Q24: Product Category
Q25: Accessories
A26: Row Labels | B26: Total Order | Q26: Electronics
A27: In-store | B27: 208 | Q27: Home
A28: Online | B28: 137 | Q28: Grand Total
A29: WhatsApp | B29: 87
A30: Grand Total | B30: 432
A32: Row Labels | B32: Returned Order
A33: In-store | B33: 13
A34: Online | B34: 15
A35: WhatsApp | B35: 10
A36: Grand Total | B36: 38
A39: Row Labels | B39: Revenue
A40: Jan | B40: 6749250 | C40: =A40 -> Jan | D40: =B40 -> 6749250
A41: Feb | B41: 5479500 | C41: =A41 -> Feb | D41: =B41 -> 5479500
A42: Mar | B42: 6306375 | C42: =A42 -> Mar | D42: =B42 -> 6306375
A43: Apr | B43: 6367700 | C43: =A43 -> Apr | D43: =B43 -> 6367700
A44: May | B44: 7556700 | C44: =A44 -> May | D44: =B44 -> 7556700
A45: Jun | B45: 5440450 | C45: =A45 -> Jun | D45: =B45 -> 5440450
...

Sheet Cleaned Data
A1: Transaction_ID | B1: Date | C1: Store_ID | D1: State | E1: Channel | F1: Product_Category | G1: Product | H1: Customer_ID | I1: Customer_Type | J1: Units | K1: Unit_Price_NGN | L1: Discount_Pct | M1: Revenue_Reported_NGN | N1: Revenue_Reported_NGN (Correct) | O1: Cost_Per_Unit_NGN | P1: Cost_Per_Unit_NGN (Correct) | Q1: Total_Cost _NGN | R1: Profit_NGN | S1: Return_Flag | T1: Sales_Rep | U1: Month | V1: Return_Flag_Index
A2: ='Raw Data'!A2 -> 100001 | B2: ='Raw Data'!B2 -> 46167 | C2: ='Raw Data'!C2 -> AB-02 | D2: =PROPER(TRIM('Raw Data'!D2)) -> Abuja | E2: ='Raw Data'!E2 -> WhatsApp | F2: =IF(PROPER(TRIM('Raw Data'!F2))="Accessory","Accessories",PROPER(TRIM('Raw Data'!F2))) -> Home | G2: ='Raw Data'!G2 -> Standing Fan | H2: ='Raw Data'!H2 -> C1141 | I2: ='Raw Data'!I2 -> New | J2: ='Raw Data'!J2 -> 1 | K2: ='Raw Data'!K2 -> 58000 | L2: ='Raw Data'!L2 -> 0 | M2: ='Raw Data'!M2 -> 58000 | N2: =J2*K2*(1-L2) -> 58000 | O2: ='Raw Data'!N2 -> 0 | P2: =IF(ISBLANK('Raw Data'!N2),AVERAGEIFS('Raw Data'!$N$2:$N$433,'Raw Data'!$G$2:$G$433,G2),'Raw Data'!N2) -> 39000 | Q2: =J2*P2 -> 39000 | R2: =N2-Q2 -> 19000 | S2: ='Raw Data'!O2 -> No | T2: ='Raw Data'!P2 -> Chinedu | U2: =TEXT(B2,"mmmm") -> May | V2: =IF(S2="No",0,1) -> 0
A3: ='Raw Data'!A3 -> 100002 | B3: ='Raw Data'!B3 -> 46129 | C3: ='Raw Data'!C3 -> LG-01 | D3: =PROPER(TRIM('Raw Data'!D3)) -> Lagos | E3: ='Raw Data'!E3 -> WhatsApp | F3: =IF(PROPER(TRIM('Raw Data'!F3))="Accessory","Accessories",PROPER(TRIM('Raw Data'!F3))) -> Electronics | G3: ='Raw Data'!G3 -> Smartphone | H3: ='Raw Data'!H3 -> C1083 | I3: ='Raw Data'!I3 -> Returning | J3: ='Raw Data'!J3 -> 5 | K3: ='Raw Data'!K3 -> 165000 | L3: ='Raw Data'!L3 -> 0.05 | M3: ='Raw Data'!M3 -> 627000 | N3: =J3*K3*(1-L3) -> 783750 | O3: ='Raw Data'!N3 -> 112000 | P3: =IF(ISBLANK('Raw Data'!N3),AVERAGEIFS('Raw Data'!$N$2:$N$433,'Raw Data'!$G$2:$G$433,G3),'Raw Data'!N3) -> 112000 | Q3: =J3*P3 -> 560000 | R3: =N3-Q3 -> 223750 | S3: ='Raw Data'!O3 -> No | T3: ='Raw Data'!P3 -> Kemi | U3: =TEXT(B3,"mmmm") -> April | V3: =IF(S3="No",0,1) -> 0
A4: ='Raw Data'!A4 -> 100003 | B4: ='Raw Data'!B4 -> 46079 | C4: ='Raw Data'!C4 -> AB-01 | D4: =PROPER(TRIM('Raw Data'!D4)) -> Abuja | E4: ='Raw Data'!E4 -> WhatsApp | F4: =IF(PROPER(TRIM('Raw Data'!F4))="Accessory","Accessories",PROPER(TRIM('Raw Data'!F4))) -> Electronics | G4: ='Raw Data'!G4 -> Earbuds | H4: ='Raw Data'!H4 -> C1029 | I4: ='Raw Data'!I4 -> Returning | J4: ='Raw Data'!J4 -> 3 | K4: ='Raw Data'!K4 -> 32000 | L4: ='Raw Data'!L4 -> 0.2 | M4: ='Raw Data'!M4 -> 76800 | N4: =J4*K4*(1-L4) -> 76800 | O4: ='Raw Data'!N4 -> 19000 | P4: =IF(ISBLANK('Raw Data'!N4),AVERAGEIFS('Raw Data'!$N$2:$N$433,'Raw Data'!$G$2:$G$433,G4),'Raw Data'!N4) -> 19000 | Q4: =J4*P4 -> 57000 | R4: =N4-Q4 -> 19800 | S4: ='Raw Data'!O4 -> No | T4: ='Raw Data'!P4 -> Chinedu | U4: =TEXT(B4,"mmmm") -> February | V4: =IF(S4="No",0,1) -> 0
A5: ='Raw Data'!A5 -> 100004 | B5: ='Raw Data'!B5 -> 46182 | C5: ='Raw Data'!C5 -> KN-01 | D5: =PROPER(TRIM('Raw Data'!D5)) -> Kano | E5: ='Raw Data'!E5 -> Online | F5: =IF(PROPER(TRIM('Raw Data'!F5))="Accessory","Accessories",PROPER(TRIM('Raw Data'!F5))) -> Electronics | G5: ='Raw Data'!G5 -> Power Bank | H5: ='Raw Data'!H5 -> C1082 | I5: ='Raw Data'!I5 -> Returning | J5: ='Raw Data'!J5 -> 4 | K5: ='Raw Data'!K5 -> 26000 | L5: ='Raw Data'!L5 -> 0 | M5: ='Raw Data'!M5 -> 104000 | N5: =J5*K5*(1-L5) -> 104000 | O5: ='Raw Data'!N5 -> 15000 | P5: =IF(ISBLANK('Raw Data'!N5),AVERAGEIFS('Raw Data'!$N$2:$N$433,'Raw Data'!$G$2:$G$433,G5),'Raw Data'!N5) -> 15000 | Q5: =J5*P5 -> 60000 | R5: =N5-Q5 -> 44000 | S5: ='Raw Data'!O5 -> No | T5: ='Raw Data'!P5 -> Grace | U5: =TEXT(B5,"mmmm") -> June | V5: =IF(S5="No",0,1) -> 0
A6: ='Raw Data'!A6 -> 100005 | B6: ='Raw Data'!B6 -> 46172 | C6: ='Raw Data'!C6 -> LG-01 | D6: =PROPER(TRIM('Raw Data'!D6)) -> Lagos | E6: ='Raw Data'!E6 -> Online | F6: =IF(PROPER(TRIM('Raw Data'!F6))="Accessory","Accessories",PROPER(TRIM('Raw Data'!F6))) -> Electronics | G6: ='Raw Data'!G6 -> Smartphone | H6: ='Raw Data'!H6 -> C1180 | I6: ='Raw Data'!I6 -> Returning | J6: ='Raw Data'!J6 -> 1 | K6: ='Raw Data'!K6 -> 165000 | L6: ='Raw Data'!L6 -> 0.05 | M6: ='Raw Data'!M6 -> 156750 | N6: =J6*K6*(1-L6) -> 156750 | O6: ='Raw Data'!N6 -> 112000 | P6: =IF(ISBLANK('Raw Data'!N6),AVERAGEIFS('Raw Data'!$N$2:$N$433,'Raw Data'!$G$2:$G$433,G6),'Raw Data'!N6) -> 112000 | Q6: =J6*P6 -> 112000 | R6: =N6-Q6 -> 44750 | S6: ='Raw Data'!O6 -> No | T6: ='Raw Data'!P6 -> Chinedu | U6: =TEXT(B6,"mmmm") -> May | V6: =IF(S6="No",0,1) -> 0
A7: ='Raw Data'!A7 -> 100006 | B7: ='Raw Data'!B7 -> 46238 | C7: ='Raw Data'!C7 -> LG-02 | D7: =PROPER(TRIM('Raw Data'!D7)) -> Lagos | E7: ='Raw Data'!E7 -> In-store | F7: =IF(PROPER(TRIM('Raw Data'!F7))="Accessory","Accessories",PROPER(TRIM('Raw Data'!F7))) -> Accessories | G7: ='Raw Data'!G7 -> USB Cable | H7: ='Raw Data'!H7 -> C1161 | I7: ='Raw Data'!I7 -> Returning | J7: ='Raw Data'!J7 -> 3 | K7: ='Raw Data'!K7 -> 6500 | L7: ='Raw Data'!L7 -> 0.1 | M7: ='Raw Data'!M7 -> 17550 | N7: =J7*K7*(1-L7) -> 17550 | O7: ='Raw Data'!N7 -> 2200 | P7: =IF(ISBLANK('Raw Data'!N7),AVERAGEIFS('Raw Data'!$N$2:$N$433,'Raw Data'!$G$2:$G$433,G7),'Raw Data'!N7) -> 2200 | Q7: =J7*P7 -> 6600 | R7: =N7-Q7 -> 10950 | S7: ='Raw Data'!O7 -> No | T7: ='Raw Data'!P7 -> Bola | U7: =TEXT(B7,"mmmm") -> August | V7: =IF(S7="No",0,1) -> 0
A8: ='Raw Data'!A8 -> 100007 | B8: ='Raw Data'!B8 -> 46090 | C8: ='Raw Data'!C8 -> LG-01 | D8: =PROPER(TRIM('Raw Data'!D8)) -> Lagos | E8: ='Raw Data'!E8 -> In-store | F8: =IF(PROPER(TRIM('Raw Data'!F8))="Accessory","Accessories",PROPER(TRIM('Raw Data'!F8))) -> Electronics | G8: ='Raw Data'!G8 -> Power Bank | H8: ='Raw Data'!H8 -> C1007 | I8: ='Raw Data'!I8 -> New | J8: ='Raw Data'!J8 -> 3 | K8: ='Raw Data'!K8 -> 26000 | L8: ='Raw Data'!L8 -> 0.1 | M8: ='Raw Data'!M8 -> 70200 | N8: =J8*K8*(1-L8) -> 70200 | O8: ='Raw Data'!N8 -> 15000 | P8: =IF(ISBLANK('Raw Data'!N8),AVERAGEIFS('Raw Data'!$N$2:$N$433,'Raw Data'!$G$2:$G$433,G8),'Raw Data'!N8) -> 15000 | Q8: =J8*P8 -> 45000 | R8: =N8-Q8 -> 25200 | S8: ='Raw Data'!O8 -> No | T8: ='Raw Data'!P8 -> Chinedu | U8: =TEXT(B8,"mmmm") -> March | V8: =IF(S8="No",0,1) -> 0
A9: ='Raw Data'!A9 -> 100008 | B9: ='Raw Data'!B9 -> 46229 | C9: ='Raw Data'!C9 -> KN-01 | D9: =PROPER(TRIM('Raw Data'!D9)) -> Kano | E9: ='Raw Data'!E9 -> Online | F9: =IF(PROPER(TRIM('Raw Data'!F9))="Accessory","Accessories",PROPER(TRIM('Raw Data'!F9))) -> Electronics | G9: ='Raw Data'!G9 -> Smartphone | H9: ='Raw Data'!H9 -> C1051 | I9: ='Raw Data'!I9 -> Returning | J9: ='Raw Data'!J9 -> 5 | K9: ='Raw Data'!K9 -> 165000 | L9: ='Raw Data'!L9 -> 0.05 | M9: ='Raw Data'!M9 -> 783750 | N9: =J9*K9*(1-L9) -> 783750 | O9: ='Raw Data'!N9 -> 112000 | P9: =IF(ISBLANK('Raw Data'!N9),AVERAGEIFS('Raw Data'!$N$2:$N$433,'Raw Data'!$G$2:$G$433,G9),'Raw Data'!N9) -> 112000 | Q9: =J9*P9 -> 560000 | R9: =N9-Q9 -> 223750 | S9: ='Raw Data'!O9 -> No | T9: ='Raw Data'!P9 -> Kemi | U9: =TEXT(B9,"mmmm") -> July | V9: =IF(S9="No",0,1) -> 0
A10: ='Raw Data'!A10 -> 100009 | B10: ='Raw Data'!B10 -> 46028 | C10: ='Raw Data'!C10 -> IB-01 | D10: =PROPER(TRIM('Raw Data'!D10)) -> Ibadan | E10: ='Raw Data'!E10 -> In-store | F10: =IF(PROPER(TRIM('Raw Data'!F10))="Accessory","Accessories",PROPER(TRIM('Raw Data'!F10))) -> Home | G10: ='Raw Data'!G10 -> Blender | H10: ='Raw Data'!H10 -> C1111 | I10: ='Raw Data'!I10 -> Returning | J10: ='Raw Data'!J10 -> 3 | K10: ='Raw Data'!K10 -> 42000 | L10: ='Raw Data'!L10 -> 0.15 | M10: ='Raw Data'!M10 -> 107100 | N10: =J10*K10*(1-L10) -> 107100 | O10: ='Raw Data'!N10 -> 28000 | P10: =IF(ISBLANK('Raw Data'!N10),AVERAGEIFS('Raw Data'!$N$2:$N$433,'Raw Data'!$G$2:$G$433,G10),'Raw Data'!N10) -> 28000 | Q10: =J10*P10 -> 84000 | R10: =N10-Q10 -> 23100 | S10: ='Raw Data'!O10 -> No | T10: ='Raw Data'!P10 -> Fatima | U10: =TEXT(B10,"mmmm") -> January | V10: =IF(S10="No",0,1) -> 0
A11: ='Raw Data'!A11 -> 100010 | B11: ='Raw Data'!B11 -> 46248 | C11: ='Raw Data'!C11 -> PH-01 | D11: =PROPER(TRIM('Raw Data'!D11)) -> Port Harcourt | E11: ='Raw Data'!E11 -> In-store | F11: =IF(PROPER(TRIM('Raw Data'!F11))="Accessory","Accessories",PROPER(TRIM('Raw Data'!F11))) -> Electronics | G11: ='Raw Data'!G11 -> Smartphone | H11: ='Raw Data'!H11 -> C1153 | I11: ='Raw Data'!I11 -> Returning | J11: ='Raw Data'!J11 -> 1 | K11: ='Raw Data'!K11 -> 165000 | L11: ='Raw Data'!L11 -> 0 | M11: ='Raw Data'!M11 -> 165000 | N11: =J11*K11*(1-L11) -> 165000 | O11: ='Raw Data'!N11 -> 112000 | P11: =IF(ISBLANK('Raw Data'!N11),AVERAGEIFS('Raw Data'!$N$2:$N$433,'Raw Data'!$G$2:$G$433,G11),'Raw Data'!N11) -> 112000 | Q11: =J11*P11 -> 112000 | R11: =N11-Q11 -> 53000 | S11: ='Raw Data'!O11 -> No | T11: ='Raw Data'!P11 -> David | U11: =TEXT(B11,"mmmm") -> August | V11: =IF(S11="No",0,1) -> 0
A12: ='Raw Data'!A12 -> 100011 | B12: ='Raw Data'!B12 -> 46200 | C12: ='Raw Data'!C12 -> LG-01 | D12: =PROPER(TRIM('Raw Data'!D12)) -> Lagos | E12: ='Raw Data'!E12 -> In-store | F12: =IF(PROPER(TRIM('Raw Data'!F12))="Accessory","Accessories",PROPER(TRIM('Raw Data'!F12))) -> Electronics | G12: ='Raw Data'!G12 -> Earbuds | H12: ='Raw Data'!H12 -> C1059 | I12: ='Raw Data'!I12 -> Returning | J12: ='Raw Data'!J12 -> 1 | K12: ='Raw Data'!K12 -> 32000 | L12: ='Raw Data'!L12 -> 0 | M12: ='Raw Data'!M12 -> 32000 | N12: =J12*K12*(1-L12) -> 32000 | O12: ='Raw Data'!N12 -> 19000 | P12: =IF(ISBLANK('Raw Data'!N12),AVERAGEIFS('Raw Data'!$N$2:$N$433,'Raw Data'!$G$2:$G$433,G12),'Raw Data'!N12) -> 19000 | Q12: =J12*P12 -> 19000 | R12: =N12-Q12 -> 13000 | S12: ='Raw Data'!O12 -> No | T12: ='Raw Data'!P12 -> David | U12: =TEXT(B12,"mmmm") -> June | V12: =IF(S12="No",0,1) -> 0
A13: ='Raw Data'!A13 -> 100012 | B13: ='Raw Data'!B13 -> 46120 | C13: ='Raw Data'!C13 -> KN-01 | D13: =PROPER(TRIM('Raw Data'!D13)) -> Kano | E13: ='Raw Data'!E13 -> Online | F13: =IF(PROPER(TRIM('Raw Data'!F13))="Accessory","Accessories",PROPER(TRIM('Raw Data'!F13))) -> Accessories | G13: ='Raw Data'!G13 -> Phone Case | H13: ='Raw Data'!H13 -> C1028 | I13: ='Raw Data'!I13 -> New | J13: ='Raw Data'!J13 -> 1 | K13: ='Raw Data'!K13 -> 9000 | L13: ='Raw Data'!L13 -> 0 | M13: ='Raw Data'!M13 -> 9000 | N13: =J13*K13*(1-L13) -> 9000 | O13: ='Raw Data'!N13 -> 3500 | P13: =IF(ISBLANK('Raw Data'!N13),AVERAGEIFS('Raw Data'!$N$2:$N$433,'Raw Data'!$G$2:$G$433,G13),'Raw Data'!N13) -> 3500 | Q13: =J13*P13 -> 3500 | R13: =N13-Q13 -> 5500 | S13: ='Raw Data'!O13 -> No | T13: ='Raw Data'!P13 -> David | U13: =TEXT(B13,"mmmm") -> April | V13: =IF(S13="No",0,1) -> 0
... A433: ='Raw Data'!A433 -> 100401 | B433: ='Raw Data'!B433 -> 46168 | C433: ='Raw Data'!C433 -> IB-01 | D433: =PROPER(TRIM('Raw Data'!D433)) -> Ibadan | E433: ='Raw Data'!E433 -> Online | F433: =IF(PROPER(TRIM('Raw Data'!F433))="Accessory","Accessories",PROPER(TRIM('Raw Data'!F433))) -> Electronics | G433: ='Raw Data'!G433 -> Smartphone | H433: ='Raw Data'!H433 -> C1158 | I433: ='Raw Data'!I433 -> Returning | J433: ='Raw Data'!J433 -> 3 | K433: ='Raw Data'!K433 -> 165000 | L433: ='Raw Data'!L433 -> 0 | M433: ='Raw Data'!M433 -> 495000 | N433: =J433*K433*(1-L433) -> 495000 | O433: ='Raw Data'!N433 -> 112000 | P433: =IF(ISBLANK('Raw Data'!N433),AVERAGEIFS('Raw Data'!$N$2:$N$433,'Raw Data'!$G$2:$G$433,G433),'Raw Data'!N433) -> 112000 | Q433: =J433*P433 -> 336000 | R433: =N433-Q433 -> 159000 | S433: ='Raw Data'!O433 -> Yes | T433: ='Raw Data'!P433 -> Fatima | U433: =TEXT(B433,"mmmm") -> May | V433: =IF(S433="No",0,1) -> 1
M435: =SUM(M2:M434) -> 47500870 | N435: =SUM(N2:N434) -> 47810625

Sheet Raw Data
A1: Transaction_ID | B1: Date | C1: Store_ID | D1: State | E1: Channel | F1: Product_Category | G1: Product | H1: Customer_ID | I1: Customer_Type | J1: Units | K1: Unit_Price_NGN | L1: Discount_Pct | M1: Revenue_Reported_NGN | N1: Cost_Per_Unit_NGN | O1: Return_Flag | P1: Sales_Rep
A2: 100001 | B2: 46167 | C2: AB-02 | D2: Abuja | E2: WhatsApp | F2: Home | G2: Standing Fan | H2: C1141 | I2: New | J2: 1 | K2: 58000 | L2: 0 | M2: 58000 | O2: No | P2: Chinedu
A3: 100002 | B3: 46129 | C3: LG-01 | D3: Lagos | E3: WhatsApp | F3: Electronics | G3: Smartphone | H3: C1083 | I3: Returning | J3: 5 | K3: 165000 | L3: 0.05 | M3: 627000 | N3: 112000 | O3: No | P3: Kemi
A4: 100003 | B4: 46079 | C4: AB-01 | D4: Abuja | E4: WhatsApp | F4: Electronics | G4: Earbuds | H4: C1029 | I4: Returning | J4: 3 | K4: 32000 | L4: 0.2 | M4: 76800 | N4: 19000 | O4: No | P4: Chinedu
A5: 100004 | B5: 46182 | C5: KN-01 | D5: Kano | E5: Online | F5: Electronics | G5: Power Bank | H5: C1082 | I5: Returning | J5: 4 | K5: 26000 | L5: 0 | M5: 104000 | N5: 15000 | O5: No | P5: Grace
A6: 100005 | B6: 46172 | C6: LG-01 | D6: Lagos | E6: Online | F6: Electronics | G6: Smartphone | H6: C1180 | I6: Returning | J6: 1 | K6: 165000 | L6: 0.05 | M6: 156750 | N6: 112000 | O6: No | P6: Chinedu
A7: 100006 | B7: 46238 | C7: LG-02 | D7: Lagos | E7: In-store | F7: Accessories | G7: USB Cable | H7: C1161 | I7: Returning | J7: 3 | K7: 6500 | L7: 0.1 | M7: 17550 | N7: 2200 | O7: No | P7: Bola
A8: 100007 | B8: 46090 | C8: LG-01 | D8: Lagos | E8: In-store | F8: Electronics | G8: Power Bank | H8: C1007 | I8: New | J8: 3 | K8: 26000 | L8: 0.1 | M8: 70200 | N8: 15000 | O8: No | P8: Chinedu
A9: 100008 | B9: 46229 | C9: KN-01 | D9: Kano | E9: Online | F9: Electronics | G9: Smartphone | H9: C1051 | I9: Returning | J9: 5 | K9: 165000 | L9: 0.05 | M9: 783750 | N9: 112000 | O9: No | P9: Kemi
A10: 100009 | B10: 46028 | C10: IB-01 | D10: Ibadan | E10: In-store | F10: Home | G10: Blender | H10: C1111 | I10: Returning | J10: 3 | K10: 42000 | L10: 0.15 | M10: 107100 | N10: 28000 | O10: No | P10: Fatima
A11: 100010 | B11: 46248 | C11: PH-01 | D11: Port Harcourt | E11: In-store | F11: Electronics | G11: Smartphone | H11: C1153 | I11: Returning | J11: 1 | K11: 165000 | L11: 0 | M11: 165000 | N11: 112000 | O11: No | P11: David
A12: 100011 | B12: 46200 | C12: LG-01 | D12: Lagos | E12: In-store | F12: Electronics | G12: Earbuds | H12: C1059 | I12: Returning | J12: 1 | K12: 32000 | L12: 0 | M12: 32000 | N12: 19000 | O12: No | P12: David
A13: 100012 | B13: 46120 | C13: KN-01 | D13: Kano | E13: Online | F13: Accessories | G13: Phone Case | H13: C1028 | I13: New | J13: 1 | K13: 9000 | L13: 0 | M13: 9000 | N13: 3500 | O13: No | P13: David
A14: 100013 | B14: 46153 | C14: IB-01 | D14: Ibadan | E14: In-store | F14: Home | G14: Electric Kettle | H14: C1192 | I14: New | J14: 2 | K14: 24000 | L14: 0 | M14: 48000 | N14: 15000 | O14: No | P14: Ibrahim
A15: 100014 | B15: 46195 | C15: AB-02 | D15: Abuja | E15: WhatsApp | F15: Accessories | G15: Backpack | H15: C1022 | I15: Returning | J15: 2 | K15: 28000 | L15: 0.25 | M15: 42000 | O15: No | P15: Fatima
A16: 100015 | B16: 46031 | C16: PH-01 | D16: Port Harcourt | E16: In-store | F16: Electronics | G16: Smartphone | H16: C1084 | I16: New | J16: 2 | K16: 165000 | L16: 0 | M16: 330000 | N16: 112000 | O16: No | P16: Grace
A17: 100016 | B17: 46228 | C17: LG-02 | D17: Lagos | E17: Online | F17: Accessories | G17: USB Cable | H17: C1123 | I17: New | J17: 1 | K17: 6500 | L17: 0.1 | M17: 4680 | N17: 2200 | O17: No | P17: Kemi
A18: 100017 | B18: 46032 | C18: KN-01 | D18: Kano | E18: WhatsApp | F18: Home | G18: Blender | H18: C1134 | I18: New | J18: 2 | K18: 42000 | L18: 0 | M18: 84000 | N18: 28000 | O18: No | P18: Ibrahim
A19: 100018 | B19: 46141 | C19: PH-01 | D19: Port Harcourt | E19: In-store | F19: Accessories | G19: USB Cable | H19: C1100 | I19: Returning | J19: 22 | K19: 6500 | L19: 0.15 | M19: 121550 | N19: 2200 | O19: No | P19: Kemi
A20: 100019 | B20: 46148 | C20: LG-01 | D20: Lagos | E20: In-store | F20: Electronics | G20: Power Bank | H20: C1189 | I20: Returning | J20: 1 | K20: 26000 | L20: 0.15 | M20: 22100 | N20: 15000 | O20: No | P20: Bola
A21: 100020 | B21: 46131 | C21: AB-02 | D21: Abuja | E21: In-store | F21: Electronics | G21: Power Bank | H21: C1050 | I21: Returning | J21: 1 | K21: 26000 | L21: 0.25 | M21: 19500 | O21: No | P21: Ibrahim
A22: 100021 | B22: 46148 | C22: AB-02 | D22: Abuja | E22: WhatsApp | F22: Electronics | G22: Power Bank | H22: C1184 | I22: New | J22: 1 | K22: 26000 | L22: 0 | M22: 26000 | N22: 15000 | O22: No | P22: Kemi
A23: 100022 | B23: 46033 | C23: IB-01 | D23: Ibadan | E23: WhatsApp | F23: Accessories | G23: Backpack | H23: C1022 | I23: New | J23: 1 | K23: 28000 | L23: 0.05 | M23: 26600 | N23: 16000 | O23: No | P23: Bola
A24: 100023 | B24: 46052 | C24: AB-01 | D24: Abuja | E24: Online | F24: Electronics | G24: Earbuds | H24: C1004 | I24: Returning | J24: 1 | K24: 32000 | L24: 0.15 | M24: 27200 | N24: 19000 | O24: No | P24: David
A25: 100024 | B25: 46150 | C25: AB-01 | D25: Abuja | E25: In-store | F25: Home | G25: Standing Fan | H25: C1034 | I25: New | J25: 2 | K25: 58000 | L25: 0.2 | M25: 92800 | O25: Yes | P25: Grace
A26: 100025 | B26: 46027 | C26: KN-01 | D26: Kano | E26: In-store | F26: Home | G26: Standing Fan | H26: C1164 | I26: Returning | J26: 5 | K26: 58000 | L26: 0.05 | M26: 275500 | N26: 39000 | O26: No | P26: David
A27: 100026 | B27: 46203 | C27: IB-01 | D27: Ibadan | E27: In-store | F27: Accessories | G27: Phone Case | H27: C1155 | I27: Returning | J27: 2 | K27: 9000 | L27: 0.1 | M27: 16200 | O27: No | P27: Chinedu
A28: 100027 | B28: 46142 | C28: KN-01 | D28: Kano | E28: WhatsApp | F28: Home | G28: Standing Fan | H28: C1073 | I28: New | J28: 4 | K28: 58000 | L28: 0.05 | M28: 220400 | N28: 39000 | O28: No | P28: David
A29: 100028 | B29: 46156 | C29: AB-01 | D29: Abuja | E29: Online | F29: Electronics | G29: Power Bank | H29: C1136 | I29: Returning | J29: 22 | K29: 26000 | L29: 0.25 | M29: 429000 | N29: 15000 | O29: No | P29: Bola
A30: 100029 | B30: 46103 | C30: AB-01 | D30: Abuja | E30: In-store | F30: Home | G30: Standing Fan | H30: C1173 | I30: Returning | J30: 5 | K30: 58000 | L30: 0.1 | M30: 261000 | O30: No | P30: Chinedu
A31: 100030 | B31: 46209 | C31: KN-01 | D31: Kano | E31: Online | F31: Electronics | G31: Power Bank | H31: C1071 | I31: New | J31: 1 | K31: 26000 | L31: 0.05 | M31: 24700 | N31: 15000 | O31: No | P31: David
A32: 100031 | B32: 46182 | C32: AB-01 | D32: Abuja | E32: In-store | F32: Home | G32: Standing Fan | H32: C1047 | I32: New | J32: 2 | K32: 58000 | L32: 0.15 | M32: 98600 | N32: 39000 | O32: No | P32: Aisha
A33: 100032 | B33: 46109 | C33: PH-01 | D33: Port Harcourt | E33: Online | F33: Home | G33: Electric Kettle | H33: C1051 | I33: New | J33: 1 | K33: 24000 | L33: 0.05 | M33: 22800 | N33: 15000 | O33: No | P33: Kemi
A34: 100033 | B34: 46152 | C34: LG-01 | D34: Lagos | E34: In-store | F34: Home | G34: Standing Fan | H34: C1094 | I34: New | J34: 3 | K34: 58000 | L34: 0 | M34: 174000 | N34: 39000 | O34: No | P34: Aisha
A35: 100034 | B35: 46157 | C35: PH-01 | D35: Port Harcourt | E35: In-store | F35: Home | G35: Standing Fan | H35: C1089 | I35: Returning | J35: 1 | K35: 58000 | L35: 0.15 | M35: 49300 | N35: 39000 | O35: No | P35: Bola
A36: 100035 | B36: 46076 | C36: KN-01 | D36: Kano | E36: In-store | F36: Accessories | G36: Backpack | H36: C1048 | I36: Returning | J36: 25 | K36: 28000 | L36: 0.05 | M36: 665000 | N36: 16000 | O36: No | P36: Ibrahim
A37: 100036 | B37: 46076 | C37: KN-01 | D37: Kano | E37: In-store | F37: Electronics | G37: Earbuds | H37: C1056 | I37: New | J37: 2 | K37: 32000 | L37: 0.05 | M37: 60800 | N37: 19000 | O37: Yes | P37: Bola
A38: 100037 | B38: 46124 | C38: AB-01 | D38: Abuja | E38: In-store | F38: Accessories | G38: Backpack | H38: C1036 | I38: New | J38: 2 | K38: 28000 | L38: 0 | M38: 56000 | N38: 16000 | O38: No | P38: Grace
A39: 100038 | B39: 46037 | C39: KN-01 | D39: Kano | E39: Online | F39: Electronics | G39: Earbuds | H39: C1138 | I39: Returning | J39: 2 | K39: 32000 | L39: 0 | M39: 64000 | N39: 19000 | O39: No | P39: Aisha
A40: 100039 | B40: 46116 | C40: AB-02 | D40: Abuja | E40: Online | F40: Accessories | G40: USB Cable | H40: C1044 | I40: New | J40: 3 | K40: 6500 | L40: 0.1 | M40: 17550 | N40: 2200 | O40: No | P40: Grace
...
